Workbook

Sheet High_BASE
A1: Variable | B1: Total_Budget | C1: SATL_Budget | D1: NATL_Budget | E1: AS_Budget | F1: BB_Budget | G1: INDO_budget | H1: SEAS_Budget | I1: NPAC_Budget | J1: ENPAC_Budget | K1: WNPAC_Budget | L1: ARCT_Budget | M1: AUSP_Budget | N1: SO_Budget | O1: CPAO_Budget
A2: FEANSOLDEP_mean | B2: 90.52 | C2: 3.448 | D2: 22.89 | E2: 6.731 | F2: 11.854 | G2: 18.585 | H2: 25.66 | I2: 5.99 | J2: 3.358 | K2: 2.703 | L2: 3.583 | M2: 0.845 | N2: 0.352 | O2: 9.167
A3: FEBBSOLDEP_mean | B3: 73.431 | C3: 7.045 | D3: 4.964 | E3: 4.971 | F3: 4.805 | G3: 9.777 | H3: 7.25 | I3: 2.17 | J3: 0.814 | K3: 1.374 | L3: 3.256 | M3: 2.422 | N3: 0.626 | O3: 35.922
A4: FEDUSOLDEP_mean | B4: 834.79 | C4: 20.042 | D4: 150.559 | E4: 187.254 | F4: 39.892 | G4: 227.147 | H4: 14.915 | I4: 7.335 | J4: 2.695 | K4: 4.711 | L4: 5.903 | M4: 38.321 | N4: 9.951 | O4: 360.618
A5: FEANTOTDEP_mean | B5: 2221.707 | C5: 70.099 | D5: 655.379 | E5: 119.677 | F5: 256.449 | G5: 376.126 | H5: 845.218 | I5: 82.718 | J5: 44.871 | K5: 38.647 | L5: 65.001 | M5: 22.549 | N5: 5.673 | O5: 98.944
A6: FEBBTOTDEP_mean | B6: 742.65 | C6: 66.496 | D6: 50.054 | E6: 49.632 | F6: 49.134 | G6: 98.766 | H6: 71.971 | I6: 19.161 | J6: 5.856 | K6: 13.427 | L6: 30.183 | M6: 24.243 | N6: 4.147 | O6: 377.63
A7: FEDUTOTDEP_mean | B7: 109530.57 | C7: 2468.582 | D7: 18033.073 | E7: 27961.134 | F7: 2633.029 | G7: 30594.163 | H7: 956.403 | I7: 632.165 | J7: 120.421 | K7: 515.358 | L7: 205.457 | M7: 5475.228 | N7: 693.377 | O7: 50472.122
A8: FESOLDEP_mean | B8: 998.741 | C8: 30.534 | D8: 178.413 | E8: 198.956 | F8: 56.552 | G8: 255.508 | H8: 47.824 | I8: 15.495 | J8: 6.868 | K8: 8.788 | L8: 12.742 | M8: 41.588 | N8: 10.929 | O8: 405.707
A9: FETOTDEP_mean | B9: 112494.93 | C9: 2605.177 | D9: 18738.506 | E9: 28130.444 | F9: 2938.611 | G9: 31069.055 | H9: 1873.592 | I9: 734.044 | J9: 171.148 | K9: 567.432 | L9: 300.641 | M9: 5522.02 | N9: 703.197 | O9: 50948.696
A11: Variable | B11: Ocean_budget | C11: SATL_Budget_oc | D11: NATL_Budget_oc | E11: AS_Budget_oc | F11: BB_Budget_oc | G11: INDO_budget_oc | H11: SEAS_Budget_oc | I11: NPAC_Budget_oc | J11: ENPAC_Budget_oc | K11: WNPAC_Budget_oc | L11: ARCT_Budget_oc | M11: AUSP_Budget_oc | N11: SO_Budget_oc | O11: CPAO_Budget_oc
A12: FEANSOLDEP_mean | B12: 36.177 | C12: 1.674 | D12: 3.912 | E12: 4.156 | F12: 4.507 | G12: 8.663 | H12: 10.684 | I12: 5.1 | J12: 3.257 | K12: 1.914 | L12: 0.615 | M12: 0.544 | N12: 0.333 | O12: 4.654
A13: FEBBSOLDEP_mean | B13: 25.907 | C13: 3.039 | D13: 0.824 | E13: 2.243 | F13: 2.306 | G13: 4.549 | H13: 3.04 | I13: 1.141 | J13: 0.763 | K13: 0.397 | L13: 0.167 | M13: 1.089 | N13: 0.6 | O13: 11.458
A14: FEDUSOLDEP_mean | B14: 304.939 | C14: 12.678 | D14: 28.371 | E14: 69.94 | F14: 23.679 | G14: 93.619 | H14: 7.571 | I14: 4.406 | J14: 2.613 | K14: 1.863 | L14: 1.233 | M14: 16.535 | N14: 9.178 | O14: 131.349
A15: FEANTOTDEP_mean | B15: 585.629 | C15: 23.79 | D15: 71.889 | E15: 56.845 | F15: 65.287 | G15: 122.132 | H15: 241.47 | I15: 61.147 | J15: 43.081 | K15: 18.866 | L15: 9.279 | M15: 11.269 | N15: 5.33 | O15: 39.323
A16: FEBBTOTDEP_mean | B16: 215.544 | C16: 23.319 | D16: 7.071 | E16: 17.807 | F16: 19.73 | G16: 37.537 | H16: 27.575 | I16: 7.92 | J16: 5.473 | K16: 2.569 | L16: 1.215 | M16: 8.861 | N16: 3.996 | O16: 98.05
A17: FEDUTOTDEP_mean | B17: 22436.444 | C17: 1220.289 | D17: 2138.997 | E17: 6638.604 | F17: 1449.562 | G17: 8088.166 | H17: 437.379 | I17: 214.161 | J17: 117.797 | K17: 99.978 | L17: 48.438 | M17: 1193.45 | N17: 587.995 | O17: 8507.568
A18: FESOLDEP_mean | B18: 367.023 | C18: 17.39 | D18: 33.107 | E18: 76.339 | F18: 30.492 | G18: 106.831 | H18: 21.294 | I18: 10.646 | J18: 6.633 | K18: 4.174 | L18: 2.015 | M18: 18.168 | N18: 10.11 | O18: 147.461
A19: FETOTDEP_mean | B19: 23237.617 | C19: 1267.398 | D19: 2217.956 | E19: 6713.256 | F19: 1534.579 | G19: 8247.835 | H19: 706.424 | I19: 283.228 | J19: 166.352 | K19: 121.413 | L19: 58.933 | M19: 1213.58 | N19: 597.321 | O19: 8644.941
B22: =B12/(B12+B13+B14) -> 0.098568755 | C22: =C12/(C12+C13+C14) -> 0.096256684 | D22: =D12/(D12+D13+D14) -> 0.11816232 | E22: =E12/(E12+E13+E14) -> 0.054441373 | F22: =F12/(F12+F13+F14) -> 0.14780926 | G22: =G12/(G12+G13+G14) -> 0.081090695 | H22: =H12/(H12+H13+H14) -> 0.50171402 | I22: =I12/(I12+I13+I14) -> 0.47900817 | ... O22: =O12/(O12+O13+O14) -> 0.031560887
B24: This matches what I reported in the original table =)
B25: *DUST IS SCALED HERE AND EVERYWHERE BY 3.8

Sheet High_RESI
A1: Variable | B1: Total_Budget | C1: SATL_Budget | D1: NATL_Budget | E1: AS_Budget | F1: BB_Budget | G1: INDO_budget | H1: SEAS_Budget | I1: NPAC_Budget | J1: ENPAC_Budget | K1: WNPAC_Budget | L1: ARCT_Budget | M1: AUSP_Budget | N1: SO_Budget | O1: CPAO_Budget
A2: FEANSOLDEP_mean | B2: 239.155 | C2: 6.139 | D2: 66.701 | E2: 15.157 | F2: 33.672 | G2: 48.83 | H2: 85.967 | I2: 10.761 | J2: 5.778 | K2: 5.098 | L2: 6.018 | M2: 2.13 | N2: 0.571 | O2: 12.04
A3: FEBBSOLDEP_mean | B3: 73.439 | C3: 7.047 | D3: 4.964 | E3: 4.971 | F3: 4.805 | G3: 9.777 | H3: 7.25 | I3: 2.17 | J3: 0.814 | K3: 1.374 | L3: 3.256 | M3: 2.422 | N3: 0.626 | O3: 35.927
A4: FEDUSOLDEP_mean | B4: 834.801 | C4: 20.037 | D4: 150.532 | E4: 187.253 | F4: 39.887 | G4: 227.14 | H4: 14.912 | I4: 7.337 | J4: 2.694 | K4: 4.713 | L4: 5.903 | M4: 38.317 | N4: 9.943 | O4: 360.681
A5: FEANTOTDEP_mean | B5: 2221.708 | C5: 70.101 | D5: 655.384 | E5: 119.68 | F5: 256.455 | G5: 376.135 | H5: 845.203 | I5: 82.718 | J5: 44.869 | K5: 38.648 | L5: 65.002 | M5: 22.549 | N5: 5.673 | O5: 98.944
A6: FEBBTOTDEP_mean | B6: 742.65 | C6: 66.492 | D6: 50.054 | E6: 49.631 | F6: 49.13 | G6: 98.761 | H6: 71.975 | I6: 19.162 | J6: 5.856 | K6: 13.428 | L6: 30.182 | M6: 24.242 | N6: 4.149 | O6: 377.633
A7: FEDUTOTDEP_mean | B7: 109523.55 | C7: 2467.05 | D7: 18031.314 | E7: 27959.998 | F7: 2632.914 | G7: 30592.911 | H7: 956.516 | I7: 632.667 | J7: 120.546 | K7: 515.738 | L7: 205.442 | M7: 5473.062 | N7: 693.241 | O7: 50471.344
A8: FESOLDEP_mean | B8: 1147.395 | C8: 33.223 | D8: 222.197 | E8: 207.381 | F8: 78.365 | G8: 285.746 | H8: 108.129 | I8: 20.268 | J8: 9.287 | K8: 11.185 | L8: 15.176 | M8: 42.869 | N8: 11.14 | O8: 408.648
A9: FETOTDEP_mean | B9: 112487.9 | C9: 2603.643 | D9: 18736.751 | E9: 28129.308 | F9: 2938.498 | G9: 31067.807 | H9: 1873.694 | I9: 734.547 | J9: 171.271 | K9: 567.815 | L9: 300.626 | M9: 5519.853 | N9: 703.063 | O9: 50947.921
B11: Ocean_budget | C11: SATL_Budget_oc | D11: NATL_Budget_oc | E11: AS_Budget_oc | F11: BB_Budget_oc | G11: INDO_budget_oc | H11: SEAS_Budget_oc | I11: NPAC_Budget_oc | J11: ENPAC_Budget_oc | K11: WNPAC_Budget_oc | L11: ARCT_Budget_oc | M11: AUSP_Budget_oc | N11: SO_Budget_oc | O11: CPAO_Budget_oc
A12: FEANSOLDEP_mean | B12: 69.533 | C12: 2.36 | D12: 8.508 | E12: 7.838 | F12: 9.156 | G12: 16.994 | H12: 24.804 | I12: 8.325 | J12: 5.583 | K12: 2.857 | L12: 0.963 | M12: 1.161 | N12: 0.543 | O12: 5.874
A13: FEBBSOLDEP_mean | B13: 25.914 | C13: 3.042 | D13: 0.824 | E13: 2.243 | F13: 2.306 | G13: 4.549 | H13: 3.04 | I13: 1.141 | J13: 0.763 | K13: 0.397 | L13: 0.167 | M13: 1.089 | N13: 0.6 | O13: 11.461
A14: FEDUSOLDEP_mean | B14: 304.946 | C14: 12.678 | D14: 28.359 | E14: 69.953 | F14: 23.678 | G14: 93.631 | H14: 7.569 | I14: 4.406 | J14: 2.612 | K14: 1.864 | L14: 1.233 | M14: 16.533 | N14: 9.168 | O14: 131.368
A15: FEANTOTDEP_mean | B15: 585.668 | C15: 23.792 | D15: 71.89 | E15: 56.846 | F15: 65.298 | G15: 122.144 | H15: 241.489 | I15: 61.146 | J15: 43.08 | K15: 18.866 | L15: 9.282 | M15: 11.272 | N15: 5.33 | O15: 39.323
A16: FEBBTOTDEP_mean | B16: 215.569 | C16: 23.332 | D16: 7.07 | E16: 17.806 | F16: 19.729 | G16: 37.535 | H16: 27.577 | I16: 7.919 | J16: 5.473 | K16: 2.568 | L16: 1.215 | M16: 8.862 | N16: 3.998 | O16: 98.06
A17: FEDUTOTDEP_mean | B17: 22433.354 | C17: 1219.32 | D17: 2138.461 | E17: 6638.033 | F17: 1449.504 | G17: 8087.537 | H17: 437.479 | I17: 214.514 | J17: 117.923 | K17: 100.208 | L17: 48.454 | M17: 1193.266 | N17: 587.037 | O17: 8507.285
A18: FESOLDEP_mean | B18: 400.392 | C18: 18.08 | D18: 37.692 | E18: 80.034 | F18: 35.14 | G18: 115.174 | H18: 35.413 | I18: 13.872 | J18: 8.958 | K18: 5.118 | L18: 2.364 | M18: 18.783 | N18: 10.311 | O18: 148.703
A19: FETOTDEP_mean | B19: 23234.591 | C19: 1266.444 | D19: 2217.422 | E19: 6712.685 | F19: 1534.531 | G19: 8247.216 | H19: 706.545 | I19: 283.579 | J19: 166.477 | K19: 121.642 | L19: 58.952 | M19: 1213.401 | N19: 596.365 | O19: 8644.667
A22: % contr. AN to all sol Fe | B22: =B12/(B12+B13+B14) -> 0.17366188 | C22: =C12/(C12+C13+C14) -> 0.13053097 | D22: =D12/(D12+D13+D14) -> 0.22573028 | E22: =E12/(E12+E13+E14) -> 0.097933378 | F22: =F12/(F12+F13+F14) -> 0.26055777 | G22: =G12/(G12+G13+G14) -> 0.14755066 | H22: =H12/(H12+H13+H14) -> 0.70042075 | I22: =I12/(I12+I13+I14) -> 0.60012976 | ... O22: =O12/(O12+O13+O14) -> 0.039501557
A23: Relative change to BASE | B23: =High_BASE!B22-High_WOOD!B22 -> -0.097652921 | C23: =High_BASE!C22-High_WOOD!C22 -> -0.12447097 | D23: =High_BASE!D22-High_WOOD!D22 -> -0.12614233 | E23: =High_BASE!E22-High_WOOD!E22 -> -0.059578855 | F23: =High_BASE!F22-High_WOOD!F22 -> -0.14977374 | G23: =High_BASE!G22-High_WOOD!G22 -> -0.090254182 | H23: =High_BASE!H22-High_WOOD!H22 -> -0.2140574 | I23: =High_BASE!I22-High_WOOD!I22 -> -0.12989608 | ... O23: =High_BASE!O22-High_WOOD!O22 -> -0.021962031

Sheet High_WOOD
A1: Variable | B1: Total_Budget | C1: SATL_Budget | D1: NATL_Budget | E1: AS_Budget | F1: BB_Budget | G1: INDO_budget | H1: SEAS_Budget | I1: NPAC_Budget | J1: ENPAC_Budget | K1: WNPAC_Budget | L1: ARCT_Budget | M1: AUSP_Budget | N1: SO_Budget | O1: CPAO_Budget
A2: FEANSOLDEP_mean | B2: 270.696 | C2: 11.224 | D2: 71.326 | E2: 18.358 | F2: 39.226 | G2: 57.584 | H2: 88.989 | I2: 11.608 | J2: 5.945 | K2: 5.781 | L2: 6.583 | M2: 2.6 | N2: 0.757 | O2: 20.027
A3: FEBBSOLDEP_mean | B3: 73.431 | C3: 7.043 | D3: 4.965 | E3: 4.971 | F3: 4.805 | G3: 9.777 | H3: 7.25 | I3: 2.169 | J3: 0.814 | K3: 1.374 | L3: 3.256 | M3: 2.422 | N3: 0.626 | O3: 35.923
A4: FEDUSOLDEP_mean | B4: 834.731 | C4: 20.014 | D4: 150.526 | E4: 187.242 | F4: 39.881 | G4: 227.123 | H4: 14.904 | I4: 7.331 | J4: 2.693 | K4: 4.709 | L4: 5.898 | M4: 38.331 | N4: 9.943 | O4: 360.661
A5: FEANTOTDEP_mean | B5: 2221.71 | C5: 70.098 | D5: 655.366 | E5: 119.68 | F5: 256.456 | G5: 376.136 | H5: 845.222 | I5: 82.716 | J5: 44.869 | K5: 38.646 | L5: 65.004 | M5: 22.549 | N5: 5.674 | O5: 98.945
A6: FEBBTOTDEP_mean | B6: 742.652 | C6: 66.495 | D6: 50.054 | E6: 49.63 | F6: 49.133 | G6: 98.762 | H6: 71.973 | I6: 19.16 | J6: 5.856 | K6: 13.427 | L6: 30.182 | M6: 24.245 | N6: 4.149 | O6: 377.631
A7: FEDUTOTDEP_mean | B7: 109517.79 | C7: 2465.277 | D7: 18027.934 | E7: 27959.651 | F7: 2632.76 | G7: 30592.411 | H7: 956.008 | I7: 631.792 | J7: 120.28 | K7: 515.118 | L7: 205.325 | M7: 5474.883 | N7: 692.868 | O7: 50471.294
A8: FESOLDEP_mean | B8: 1178.858 | C8: 38.281 | D8: 226.816 | E8: 210.571 | F8: 83.912 | G8: 294.484 | H8: 111.143 | I8: 21.108 | J8: 9.452 | K8: 11.864 | L8: 15.737 | M8: 43.352 | N8: 11.326 | O8: 416.611
A9: FETOTDEP_mean | B9: 112482.15 | C9: 2601.87 | D9: 18733.354 | E9: 28128.961 | F9: 2938.349 | G9: 31067.31 | H9: 1873.203 | I9: 733.668 | J9: 171.005 | K9: 567.191 | L9: 300.511 | M9: 5521.676 | N9: 702.69 | O9: 50947.87
B11: Ocean_budget | C11: SATL_Budget_oc | D11: NATL_Budget_oc | E11: AS_Budget_oc | F11: BB_Budget_oc | G11: INDO_budget_oc | H11: SEAS_Budget_oc | I11: NPAC_Budget_oc | J11: ENPAC_Budget_oc | K11: WNPAC_Budget_oc | L11: ARCT_Budget_oc | M11: AUSP_Budget_oc | N11: SO_Budget_oc | O11: CPAO_Budget_oc
A12: FEANSOLDEP_mean | B12: 80.767 | C12: 4.447 | D12: 9.437 | E12: 9.289 | F12: 11.007 | G12: 20.297 | H12: 26.704 | I12: 8.63 | J12: 5.748 | K12: 3.001 | L12: 1.07 | M12: 1.387 | N12: 0.718 | O12: 8.078
A13: FEBBSOLDEP_mean | B13: 25.91 | C13: 3.039 | D13: 0.824 | E13: 2.243 | F13: 2.306 | G13: 4.549 | H13: 3.04 | I13: 1.141 | J13: 0.763 | K13: 0.397 | L13: 0.167 | M13: 1.089 | N13: 0.6 | O13: 11.46
A14: FEDUSOLDEP_mean | B14: 304.934 | C14: 12.661 | D14: 28.367 | E14: 69.936 | F14: 23.675 | G14: 93.611 | H14: 7.564 | I14: 4.402 | J14: 2.61 | K14: 1.862 | L14: 1.232 | M14: 16.538 | N14: 9.17 | O14: 131.388
A15: FEANTOTDEP_mean | B15: 585.655 | C15: 23.791 | D15: 71.891 | E15: 56.844 | F15: 65.295 | G15: 122.139 | H15: 241.479 | I15: 61.146 | J15: 43.08 | K15: 18.866 | L15: 9.28 | M15: 11.272 | N15: 5.331 | O15: 39.324
A16: FEBBTOTDEP_mean | B16: 215.553 | C16: 23.325 | D16: 7.071 | E16: 17.805 | F16: 19.728 | G16: 37.533 | H16: 27.576 | I16: 7.919 | J16: 5.473 | K16: 2.568 | L16: 1.216 | M16: 8.862 | N16: 3.998 | O16: 98.054
A17: FEDUTOTDEP_mean | B17: 22430.916 | C17: 1218.363 | D17: 2137.841 | E17: 6636.823 | F17: 1449.401 | G17: 8086.224 | H17: 437.287 | I17: 214.022 | J17: 117.659 | K17: 99.968 | L17: 48.407 | M17: 1193.555 | N17: 587.365 | O17: 8507.852
A18: FESOLDEP_mean | B18: 411.612 | C18: 20.147 | D18: 38.628 | E18: 81.468 | F18: 36.988 | G18: 118.456 | H18: 37.308 | I18: 14.174 | J18: 9.121 | K18: 5.26 | L18: 2.469 | M18: 19.014 | N18: 10.488 | O18: 150.927
A19: FETOTDEP_mean | B19: 23232.124 | C19: 1265.48 | D19: 2216.803 | E19: 6711.472 | F19: 1534.425 | G19: 8245.897 | H19: 706.341 | I19: 283.087 | J19: 166.212 | K19: 121.402 | L19: 58.903 | M19: 1213.69 | N19: 596.694 | O19: 8645.229
A22: % contr. AN to all sol Fe | B22: =B12/(B12+B13+B14) -> 0.19622168 | C22: =C12/(C12+C13+C14) -> 0.22072765 | D22: =D12/(D12+D13+D14) -> 0.24430465 | E22: =E12/(E12+E13+E14) -> 0.11402023 | F22: =F12/(F12+F13+F14) -> 0.297583 | G22: =G12/(G12+G13+G14) -> 0.17134488 | H22: =H12/(H12+H13+H14) -> 0.71577142 | I22: =I12/(I12+I13+I14) -> 0.60890425 | ... O22: =O12/(O12+O13+O14) -> 0.053522919
A23: Relative change to BASE | B23: =High_BASE!B22-High_WOOD!B22 -> -0.097652921 | C23: =High_BASE!C22-High_WOOD!C22 -> -0.12447097 | D23: =High_BASE!D22-High_WOOD!D22 -> -0.12614233 | E23: =High_BASE!E22-High_WOOD!E22 -> -0.059578855 | F23: =High_BASE!F22-High_WOOD!F22 -> -0.14977374 | G23: =High_BASE!G22-High_WOOD!G22 -> -0.090254182 | H23: =High_BASE!H22-High_WOOD!H22 -> -0.2140574 | I23: =High_BASE!I22-High_WOOD!I22 -> -0.12989608 | ... O23: =High_BASE!O22-High_WOOD!O22 -> -0.021962031
A25: Relative change in AN to BASE | B25: =1-(B12/High_BASE!B12) -> -1.2325511 | C25: =1-(C12/High_BASE!C12) -> -1.6565114 | D25: =1-(D12/High_BASE!D12) -> -1.4123211 | E25: =1-(E12/High_BASE!E12) -> -1.2350818 | F25: =1-(F12/High_BASE!F12) -> -1.442201 | G25: =1-(G12/High_BASE!G12) -> -1.3429528 | H25: =1-(H12/High_BASE!H12) -> -1.4994384 | I25: =1-(I12/High_BASE!I12) -> -0.69215686 | ... O25: =1-(O12/High_BASE!O12) -> -0.73571122

Sheet ocean_dep_soluble_only_HIGH
A1: Simulation | B1: Scenario | C1: Variable | D1: Ocean_budget | E1: SATL_Budget | F1: NATL_Budget | G1: AS_Budget | H1: BB_Budget | I1: INDO_budget | J1: SEAS_Budget | K1: NPAC_Budget | L1: ENPAC_Budget | M1: WNPAC_Budget | N1: ARCT_Budget | O1: AUSP_Budget | P1: SO_Budget | Q1: CPAO_Budget
A2: V1 | B2: SSP370mid | C2: FEANSOLDEP_mean | D2: 0.03625371 | E2: 0.0015968915 | F2: 0.0030240997 | G2: 0.0045489072 | H2: 0.0048854303 | I2: 0.0094343375 | J2: 0.011179376 | K2: 0.0051294588 | L2: 0.0051294588 | M2: 0.0051294588 | N2: 0.00052359882 | O2: 0.00046931017 | P2: 0.00032628324 | Q2: 0.004570354
A3: V3 | B3: SSP370mid | C3: FEANSOLDEP_mean | D3: 0.07568871 | E3: 0.0042505395 | F3: 0.0070888841 | G3: 0.010330295 | H3: 0.011118847 | I3: 0.021449142 | J3: 0.023351955 | K3: 0.0079184605 | L3: 0.0079184605 | M3: 0.0079184605 | N3: 0.00083099478 | O3: 0.0012301359 | P3: 0.00072680325 | Q3: 0.0088417959
A4: V1 | B4: SSP370end | C4: FEANSOLDEP_mean | D4: 0.028831399 | E4: 0.0011937339 | F4: 0.0024025237 | G4: 0.0038585244 | H4: 0.0037855354 | I4: 0.0076440598 | J4: 0.0082715453 | K4: 0.0037500823 | L4: 0.0037500823 | M4: 0.0037500823 | N4: 0.00045222168 | O4: 0.00033564386 | P4: 0.00026188438 | Q4: 0.0045197038
A5: V3 | B5: SSP370end | C5: FEANSOLDEP_mean | D5: 0.048688867 | E5: 0.0025122757 | F5: 0.0040400736 | G5: 0.0077738391 | H5: 0.0070720537 | I5: 0.014845893 | J5: 0.012472232 | K5: 0.0046609671 | L5: 0.0046609671 | M5: 0.0046609671 | N5: 0.00057474992 | O5: 0.000634796 | P5: 0.00047367231 | Q5: 0.0084742079
A6: V1 | B6: PD | C6: FEANSOLDEP_mean | D6: =High_BASE!B12*0.001 -> 0.036177 | E6: =High_BASE!C12*0.001 -> 0.001674 | F6: =High_BASE!D12*0.001 -> 0.003912 | G6: =High_BASE!E12*0.001 -> 0.004156 | H6: =High_BASE!F12*0.001 -> 0.004507 | I6: =High_BASE!G12*0.001 -> 0.008663 | J6: =High_BASE!H12*0.001 -> 0.010684 | K6: =High_BASE!I12*0.001 -> 0.0051 | ... Q6: =High_BASE!O12*0.001 -> 0.004654
A7: V2 | B7: PD | C7: FEANSOLDEP_mean | D7: =High_RESI!B12*0.001 -> 0.069533 | E7: =High_RESI!C12*0.001 -> 0.00236 | F7: =High_RESI!D12*0.001 -> 0.008508 | G7: =High_RESI!E12*0.001 -> 0.007838 | H7: =High_RESI!F12*0.001 -> 0.009156 | I7: =High_RESI!G12*0.001 -> 0.016994 | J7: =High_RESI!H12*0.001 -> 0.024804 | K7: =High_RESI!I12*0.001 -> 0.008325 | ... Q7: =High_RESI!O12*0.001 -> 0.005874
A8: V3 | B8: PD | C8: FEANSOLDEP_mean | D8: =High_WOOD!B12*0.001 -> 0.080767 | E8: =High_WOOD!C12*0.001 -> 0.004447 | F8: =High_WOOD!D12*0.001 -> 0.009437 | G8: =High_WOOD!E12*0.001 -> 0.009289 | H8: =High_WOOD!F12*0.001 -> 0.011007 | I8: =High_WOOD!G12*0.001 -> 0.020297 | J8: =High_WOOD!H12*0.001 -> 0.026704 | K8: =High_WOOD!I12*0.001 -> 0.00863 | ... Q8: =High_WOOD!O12*0.001 -> 0.008078
A9: V1 | B9: PI | C9: FEANSOLDEP_mean | D9: 4.2146529e-05 | E9: 3.3101731e-07 | F9: 7.9332409e-06 | G9: 7.6788678e-06 | H9: 8.2304285e-06 | I9: 1.5909296e-05 | J9: 8.6004481e-06 | K9: 2.7031065e-06 | L9: 2.7031065e-06 | M9: 2.7031065e-06 | N9: 1.0167667e-06 | O9: 2.7349798e-07 | P9: 1.3719005e-07 | Q9: 5.2419648e-06
A10: V3 | B10: PI | C10: FEANSOLDEP_mean | D10: 4.2146529e-05 | E10: 3.3101731e-07 | F10: 7.9332409e-06 | G10: 7.6788678e-06 | H10: 8.2304285e-06 | I10: 1.5909296e-05 | J10: 8.6004481e-06 | K10: 2.7031065e-06 | L10: 2.7031065e-06 | M10: 2.7031065e-06 | N10: 1.0167667e-06 | O10: 2.7349798e-07 | P10: 1.3719005e-07 | Q10: 5.2419648e-06
A11: V1 | B11: SSP370mid | C11: FEBBSOLDEP_mean | D11: 0.025632377 | E11: 0.0030808448 | F11: 0.00087537307 | G11: 0.0019873361 | H11: 0.0035749645 | I11: 0.0055623005 | J11: 0.0042741562 | K11: 0.0014355441 | L11: 0.0014355441 | M11: 0.0014355441 | N11: 0.00017578591 | O11: 0.0013213256 | P11: 0.00057596816 | Q11: 0.0083310787
A12: V3 | B12: SSP370mid | C12: FEBBSOLDEP_mean | D12: 0.02563428 | E12: 0.0030818985 | F12: 0.00087537567 | G12: 0.001987362 | H12: 0.0035751461 | I12: 0.0055625081 | J12: 0.0042742144 | K12: 0.0014356961 | L12: 0.0014356961 | M12: 0.0014356961 | N12: 0.00017580105 | O12: 0.0013213651 | P12: 0.00057593403 | Q12: 0.0083314868
A13: V1 | B13: SSP370end | C13: FEBBSOLDEP_mean | D13: 0.024742145 | E13: 0.0027422827 | F13: 0.00088559515 | G13: 0.001923601 | H13: 0.0034379271 | I13: 0.005361528 | J13: 0.0041616318 | K13: 0.001434976 | L13: 0.001434976 | M13: 0.001434976 | N13: 0.00017798797 | O13: 0.0013102638 | P13: 0.00054865607 | Q13: 0.0081192237
A14: V3 | B14: SSP370end | C14: FEBBSOLDEP_mean | D14: 0.024740587 | E14: 0.0027410963 | F14: 0.00088555687 | G14: 0.0019235964 | H14: 0.0034372095 | I14: 0.0053608059 | J14: 0.0041617881 | K14: 0.0014349769 | L14: 0.0014349769 | M14: 0.0014349769 | N14: 0.00017801224 | O14: 0.0013103606 | P14: 0.00054870411 | Q14: 0.0081192862
A15: V1 | B15: PD | C15: FEBBSOLDEP_mean | D15: 0.025907408 | E15: 0.0030390312 | F15: 0.00082449961 | G15: 0.0022428416 | H15: 0.0023061849 | I15: 0.0045490265 | J15: 0.0030395564 | K15: 0.001141419 | L15: 0.001141419 | M15: 0.001141419 | N15: 0.00016691472 | O15: 0.0010890768 | P15: 0.00059995294 | Q15: 0.011457931
A16: V2 | B16: PD | C16: FEBBSOLDEP_mean | D16: 0.025913861 | E16: 0.0030418274 | F16: 0.00082446672 | G16: 0.0022428263 | H16: 0.0023061785 | I16: 0.0045490048 | J16: 0.0030399013 | K16: 0.0011413862 | L16: 0.0011413862 | M16: 0.0011413862 | N16: 0.00016688468 | O16: 0.0010892009 | P16: 0.00060019807 | Q16: 0.01146099
A17: V3 | B17: PD | C17: FEBBSOLDEP_mean | D17: 0.025910233 | E17: 0.0030392764 | F17: 0.00082448366 | G17: 0.0022426127 | H17: 0.002306218 | I17: 0.0045488307 | J17: 0.0030397406 | K17: 0.0011413396 | L17: 0.0011413396 | M17: 0.0011413396 | N17: 0.00016693016 | O17: 0.0010891571 | P17: 0.00060006879 | Q17: 0.011460406
A18: V1 | B18: PI | C18: FEBBSOLDEP_mean | D18: 0.048614641 | E18: 0.012503054 | F18: 0.0030122422 | G18: 0.0037890532 | H18: 0.0028939269 | I18: 0.0066829801 | J18: 0.0045278814 | K18: 0.0025121785 | L18: 0.0025121785 | M18: 0.0025121785 | N18: 0.000573717 | O18: 0.0013407074 | P18: 0.0016286736 | Q18: 0.015833206
A19: V3 | B19: PI | C19: FEBBSOLDEP_mean | D19: 0.0486 | E19: 0.0125 | F19: 0.003 | G19: 0.0038 | H19: 0.0029 | I19: 0.0067 | J19: 0.0045 | K19: 0.0025 | L19: 0.0025 | M19: 0.0025 | N19: 0.0006 | O19: 0.0013 | P19: 0.0016 | Q19: 0.0158
A20: V1 | B20: SSP370mid | C20: FEDUSOLDEP_mean | D20: 0.31511086 | E20: 0.013792339 | F20: 0.02961793 | G20: 0.071313733 | H20: 0.024030682 | I20: 0.095344415 | J20: 0.0076958801 | K20: 0.0045100481 | L20: 0.0045100481 | M20: 0.0045100481 | N20: 0.0012834713 | O20: 0.016867353 | P20: 0.009705935 | Q20: 0.13629349
... A28: V3 | B28: PI | C28: FEDUSOLDEP_mean | D28: 0.2339 | E28: 0.0104 | F28: 0.0214 | G28: 0.0512 | H28: 0.0168 | I28: 0.068 | J28: 0.006 | K28: 0.0038 | L28: 0.0038 | M28: 0.0038 | N28: 0.0009 | O28: 0.0134 | P28: 0.0074 | Q28: 0.1026
P31: =SUM(Q5+Q14+Q23) -> 0.15613624
P32: =SUM(Q3+Q12+Q21) -> 0.15350796
Q34: =P32/P31 -> 0.9831668
D90: Gg a-1 | E90: % contribution
C91: v1 (sum) | D91: =(D6+D15+D24)*1000 -> 367.02316
C92: FEANSOLDEP_mean | D92: =D6*1000 -> 36.177 | E92: =D92/D$91 -> 0.098568713
C93: FEBBSOLDEP_mean | D93: =D15*1000 -> 25.907408 | E93: =D93/D$91 -> 0.070587938
C94: FEDUSOLDEP_mean | D94: =D24*1000 -> 304.93875 | E94: =D94/D$91 -> 0.83084335
C95: v2 (sum) | D95: =SUM(D7+D16+D25)*1000 -> 400.39234
C96: FEANSOLDEP_mean | D96: =D7*1000 -> 69.533 | E96: =D96/D$95 -> 0.17366216
C97: FEBBSOLDEP_mean | D97: 25.907408 | E97: =D97/D$95 -> 0.064705054
C98: FEDUSOLDEP_mean | D98: 304.93875 | E98: =D98/D$95 -> 0.76159986
C99: v3 (sum) | D99: =SUM(D8+D17+D26)*1000 -> 411.61154
C100: FEANSOLDEP_mean | D100: =D8*1000 -> 80.767 | E100: =D100/D$99 -> 0.19622142
C101: FEBBSOLDEP_mean | D101: 25.907408 | E101: =D101/D$99 -> 0.062941404
C102: FEDUSOLDEP_mean | D102: 304.93875 | E102: =D102/D$99 -> 0.74084111

Sheet Low_BASE
A1: Variable | B1: Total_Budget | C1: SATL_Budget | D1: NATL_Budget | E1: AS_Budget | F1: BB_Budget | G1: INDO_budget | H1: SEAS_Budget | I1: NPAC_Budget | J1: ENPAC_Budget | K1: WNPAC_Budget | L1: ARCT_Budget | M1: AUSP_Budget | N1: SO_Budget | O1: CPAO_Budget
A2: FEANSOLDEP_mean | B2: 90.533 | C2: 3.447 | D2: 22.886 | E2: 6.73 | F2: 11.859 | G2: 18.59 | H2: 25.673 | I2: 5.993 | J2: 3.361 | K2: 2.704 | L2: 3.583 | M2: 0.845 | N2: 0.352 | O2: 9.165
A3: FEBBSOLDEP_mean | B3: 73.409 | C3: 7.038 | D3: 4.964 | E3: 4.97 | F3: 4.804 | G3: 9.773 | H3: 7.25 | I3: 2.169 | J3: 0.814 | K3: 1.373 | L3: 3.256 | M3: 2.421 | N3: 0.625 | O3: 35.912
A4: FEDUSOLDEP_mean | B4: 832.343 | C4: 19.993 | D4: 150.076 | E4: 186.782 | F4: 39.81 | G4: 226.593 | H4: 14.909 | I4: 7.321 | J4: 2.692 | K4: 4.7 | L4: 5.883 | M4: 38.326 | N4: 9.955 | O4: 359.289
A5: FEANTOTDEP_mean | B5: 2221.708 | C5: 70.105 | D5: 655.413 | E5: 119.686 | F5: 256.501 | G5: 376.187 | H5: 845.094 | I5: 82.747 | J5: 44.9 | K5: 38.647 | L5: 65.001 | M5: 22.548 | N5: 5.672 | O5: 98.943
A6: FEBBTOTDEP_mean | B6: 742.649 | C6: 66.496 | D6: 50.057 | E6: 49.634 | F6: 49.13 | G6: 98.764 | H6: 71.972 | I6: 19.162 | J6: 5.857 | K6: 13.427 | L6: 30.18 | M6: 24.243 | N6: 4.146 | O6: 377.629
A7: FEDUTOTDEP_mean | B7: 109175.6 | C7: 2464.78 | D7: 17972.609 | E7: 27877.241 | F7: 2628.278 | G7: 30505.519 | H7: 959.257 | I7: 631.249 | J7: 120.289 | K7: 514.568 | L7: 204.785 | M7: 5474.598 | N7: 693.978 | O7: 50268.825
A8: FESOLDEP_mean | B8: 996.285 | C8: 30.477 | D8: 177.926 | E8: 198.482 | F8: 56.473 | G8: 254.955 | H8: 47.831 | I8: 15.483 | J8: 6.867 | K8: 8.777 | L8: 12.722 | M8: 41.592 | N8: 10.932 | O8: 404.366
A9: FETOTDEP_mean | B9: 112139.96 | C9: 2601.381 | D9: 18678.079 | E9: 28046.56 | F9: 2933.909 | G9: 30980.47 | H9: 1876.323 | I9: 733.158 | J9: 171.046 | K9: 566.643 | L9: 299.966 | M9: 5521.389 | N9: 703.796 | O9: 50745.396
B11: Ocean_budget | C11: SATL_Budget_oc | D11: NATL_Budget_oc | E11: AS_Budget_oc | F11: BB_Budget_oc | G11: INDO_budget_oc | H11: SEAS_Budget_oc | I11: NPAC_Budget_oc | J11: ENPAC_Budget_oc | K11: WNPAC_Budget_oc | L11: ARCT_Budget_oc | M11: AUSP_Budget_oc | N11: SO_Budget_oc | O11: CPAO_Budget_oc
A12: FEANSOLDEP_mean | B12: 36.189 | C12: 1.674 | D12: 3.911 | E12: 4.155 | F12: 4.51 | G12: 8.666 | H12: 10.691 | I12: 5.102 | J12: 3.259 | K12: 1.915 | L12: 0.615 | M12: 0.544 | N12: 0.333 | O12: 4.654
A13: FEBBSOLDEP_mean | B13: 25.903 | C13: 3.038 | D13: 0.825 | E13: 2.242 | F13: 2.305 | G13: 4.547 | H13: 3.039 | I13: 1.141 | J13: 0.763 | K13: 0.396 | L13: 0.167 | M13: 1.089 | N13: 0.6 | O13: 11.457
A14: FEDUSOLDEP_mean | B14: 304.209 | C14: 12.648 | D14: 28.283 | E14: 69.83 | F14: 23.633 | G14: 93.464 | H14: 7.56 | I14: 4.395 | J14: 2.609 | K14: 1.857 | L14: 1.228 | M14: 16.542 | N14: 9.179 | O14: 130.909
A15: FEANTOTDEP_mean | B15: 585.744 | C15: 23.794 | D15: 71.909 | E15: 56.851 | F15: 65.325 | G15: 122.176 | H15: 241.485 | I15: 61.177 | J15: 43.11 | K15: 18.867 | L15: 9.28 | M15: 11.268 | N15: 5.329 | O15: 39.326
A16: FEBBTOTDEP_mean | B16: 215.546 | C16: 23.331 | D16: 7.072 | E16: 17.801 | F16: 19.73 | G16: 37.532 | H16: 27.576 | I16: 7.919 | J16: 5.474 | K16: 2.567 | L16: 1.215 | M16: 8.861 | N16: 3.995 | O16: 98.045
A17: FEDUTOTDEP_mean | B17: 22394.733 | C17: 1218.766 | D17: 2131.862 | E17: 6633.939 | F17: 1447.338 | G17: 8081.276 | H17: 437.657 | I17: 213.775 | J17: 117.656 | K17: 99.727 | L17: 48.253 | M17: 1193.862 | N17: 587.957 | O17: 8481.324
A18: FESOLDEP_mean | B18: 366.3 | C18: 17.36 | D18: 33.019 | E18: 76.228 | F18: 30.449 | G18: 106.676 | H18: 21.29 | I18: 10.639 | J18: 6.632 | K18: 4.168 | L18: 2.01 | M18: 18.175 | N18: 10.112 | O18: 147.02
A19: FETOTDEP_mean | B19: 23196.023 | C19: 1265.891 | D19: 2210.843 | E19: 6708.591 | F19: 1532.393 | G19: 8240.984 | H19: 706.717 | I19: 282.871 | J19: 166.24 | K19: 121.161 | L19: 58.749 | M19: 1213.991 | N19: 597.281 | O19: 8618.696
A22: % contr. AN to all sol Fe | B22: =B12/(B12+B13+B14) -> 0.098795799 | C22: =C12/(C12+C13+C14) -> 0.096428571 | D22: =D12/(D12+D13+D14) -> 0.11844695 | E22: =E12/(E12+E13+E14) -> 0.054508245 | F22: =F12/(F12+F13+F14) -> 0.14812139 | G22: =G12/(G12+G13+G14) -> 0.08123588 | H22: =H12/(H12+H13+H14) -> 0.50216064 | I22: =I12/(I12+I13+I14) -> 0.47960143 | ... O22: =O12/(O12+O13+O14) -> 0.031655557

Sheet Low_RESI
A1: Variable | B1: Total_Budget | C1: SATL_Budget | D1: NATL_Budget | E1: AS_Budget | F1: BB_Budget | G1: INDO_budget | H1: SEAS_Budget | I1: NPAC_Budget | J1: ENPAC_Budget | K1: WNPAC_Budget | L1: ARCT_Budget | M1: AUSP_Budget | N1: SO_Budget | O1: CPAO_Budget
A2: FEANSOLDEP_mean | B2: 95.735 | C2: 3.541 | D2: 24.419 | E2: 7.025 | F2: 12.623 | G2: 19.648 | H2: 27.784 | I2: 6.16 | J2: 3.445 | K2: 2.788 | L2: 3.668 | M2: 0.89 | N2: 0.36 | O2: 9.266
A3: FEBBSOLDEP_mean | B3: 73.411 | C3: 7.04 | D3: 4.965 | E3: 4.97 | F3: 4.804 | G3: 9.773 | H3: 7.249 | I3: 2.169 | J3: 0.814 | K3: 1.374 | L3: 3.256 | M3: 2.421 | N3: 0.625 | O3: 35.911
A4: FEDUSOLDEP_mean | B4: 832.327 | C4: 20.017 | D4: 150.041 | E4: 186.793 | F4: 39.819 | G4: 226.612 | H4: 14.902 | I4: 7.322 | J4: 2.689 | K4: 4.703 | L4: 5.883 | M4: 38.326 | N4: 9.956 | O4: 359.268
A5: FEANTOTDEP_mean | B5: 2221.71 | C5: 70.105 | D5: 655.414 | E5: 119.682 | F5: 256.506 | G5: 376.187 | H5: 845.083 | I5: 82.755 | J5: 44.904 | K5: 38.651 | L5: 65.003 | M5: 22.548 | N5: 5.672 | O5: 98.943
A6: FEBBTOTDEP_mean | B6: 742.649 | C6: 66.5 | D6: 50.058 | E6: 49.635 | F6: 49.131 | G6: 98.766 | H6: 71.969 | I6: 19.162 | J6: 5.858 | K6: 13.426 | L6: 30.181 | M6: 24.243 | N6: 4.146 | O6: 377.625
A7: FEDUTOTDEP_mean | B7: 109167.74 | C7: 2464.788 | D7: 17970.723 | E7: 27877.322 | F7: 2628.68 | G7: 30506.002 | H7: 957.978 | I7: 631.521 | J7: 120.022 | K7: 515.091 | L7: 204.84 | M7: 5473.518 | N7: 694.051 | O7: 50264.319
A8: FESOLDEP_mean | B8: 1001.473 | C8: 30.598 | D8: 179.425 | E8: 198.787 | F8: 57.246 | G8: 256.033 | H8: 49.935 | I8: 15.651 | J8: 6.949 | K8: 8.864 | L8: 12.807 | M8: 41.637 | N8: 10.941 | O8: 404.445
A9: FETOTDEP_mean | B9: 112132.1 | C9: 2601.392 | D9: 18676.195 | E9: 28046.639 | F9: 2934.317 | G9: 30980.956 | H9: 1875.03 | I9: 733.438 | J9: 170.784 | K9: 567.169 | L9: 300.024 | M9: 5520.308 | N9: 703.869 | O9: 50740.887
B11: Ocean_budget | C11: SATL_Budget_oc | D11: NATL_Budget_oc | E11: AS_Budget_oc | F11: BB_Budget_oc | G11: INDO_budget_oc | H11: SEAS_Budget_oc | I11: NPAC_Budget_oc | J11: ENPAC_Budget_oc | K11: WNPAC_Budget_oc | L11: ARCT_Budget_oc | M11: AUSP_Budget_oc | N11: SO_Budget_oc | O11: CPAO_Budget_oc
A12: FEANSOLDEP_mean | B12: 37.354 | C12: 1.697 | D12: 4.072 | E12: 4.285 | F12: 4.672 | G12: 8.957 | H12: 11.184 | I12: 5.215 | J12: 3.341 | K12: 1.948 | L12: 0.627 | M12: 0.565 | N12: 0.34 | O12: 4.697
A13: FEBBSOLDEP_mean | B13: 25.9 | C13: 3.037 | D13: 0.825 | E13: 2.242 | F13: 2.306 | G13: 4.547 | H13: 3.039 | I13: 1.141 | J13: 0.763 | K13: 0.397 | L13: 0.167 | M13: 1.089 | N13: 0.6 | O13: 11.455
A14: FEDUSOLDEP_mean | B14: 304.232 | C14: 12.667 | D14: 28.271 | E14: 69.841 | F14: 23.638 | G14: 93.479 | H14: 7.558 | I14: 4.393 | J14: 2.607 | K14: 1.856 | L14: 1.229 | M14: 16.539 | N14: 9.179 | O14: 130.918
A15: FEANTOTDEP_mean | B15: 585.748 | C15: 23.793 | D15: 71.907 | E15: 56.853 | F15: 65.323 | G15: 122.176 | H15: 241.483 | I15: 61.184 | J15: 43.114 | K15: 18.871 | L15: 9.281 | M15: 11.268 | N15: 5.329 | O15: 39.327
A16: FEBBTOTDEP_mean | B16: 215.533 | C16: 23.319 | D16: 7.072 | E16: 17.803 | F16: 19.732 | G16: 37.535 | H16: 27.576 | I16: 7.921 | J16: 5.475 | K16: 2.568 | L16: 1.215 | M16: 8.862 | N16: 3.995 | O16: 98.037
A17: FEDUTOTDEP_mean | B17: 22392.775 | C17: 1219.217 | D17: 2131.652 | E17: 6633.883 | F17: 1447.364 | G17: 8081.247 | H17: 437.282 | I17: 213.378 | J17: 117.394 | K17: 99.575 | L17: 48.277 | M17: 1193.688 | N17: 587.917 | O17: 8480.118
A18: FESOLDEP_mean | B18: 367.487 | C18: 17.402 | D18: 33.167 | E18: 76.367 | F18: 30.616 | G18: 106.984 | H18: 21.782 | I18: 10.749 | J18: 6.711 | K18: 4.2 | L18: 2.022 | M18: 18.193 | N18: 10.118 | O18: 147.069
A19: FETOTDEP_mean | B19: 23194.055 | C19: 1266.329 | D19: 2210.631 | E19: 6708.539 | F19: 1532.419 | G19: 8240.958 | H19: 706.341 | I19: 282.483 | J19: 165.984 | K19: 121.014 | L19: 58.773 | M19: 1213.817 | N19: 597.241 | O19: 8617.482
A22: % contr. AN to all sol Fe | B22: =B12/(B12+B13+B14) -> 0.10164741 | C22: =C12/(C12+C13+C14) -> 0.097523131 | D22: =D12/(D12+D13+D14) -> 0.12276893 | E22: =E12/(E12+E13+E14) -> 0.056109889 | F22: =F12/(F12+F13+F14) -> 0.15259995 | G22: =G12/(G12+G13+G14) -> 0.083723582 | H22: =H12/(H12+H13+H14) -> 0.51347505 | I22: =I12/(I12+I13+I14) -> 0.48516141 | ... O22: =O12/(O12+O13+O14) -> 0.031937173
A23: Relative change to BASE | B23: =Low_BASE!B22-Low_RESI!B22 -> -0.0028516106 | C23: =Low_BASE!C22-Low_RESI!C22 -> -0.0010945594 | D23: =Low_BASE!D22-Low_RESI!D22 -> -0.0043219791 | E23: =Low_BASE!E22-Low_RESI!E22 -> -0.0016016438 | F23: =Low_BASE!F22-Low_RESI!F22 -> -0.0044785605 | G23: =Low_BASE!G22-Low_RESI!G22 -> -0.002487702 | H23: =Low_BASE!H22-Low_RESI!H22 -> -0.011314408 | I23: =Low_BASE!I22-Low_RESI!I22 -> -0.0055599815 | ... O23: =Low_BASE!O22-Low_RESI!O22 -> -0.00028161571

Sheet Low_WOOD
A1: Variable | B1: Total_Budget | C1: SATL_Budget | D1: NATL_Budget | E1: AS_Budget | F1: BB_Budget | G1: INDO_budget | H1: SEAS_Budget | I1: NPAC_Budget | J1: ENPAC_Budget | K1: WNPAC_Budget | L1: ARCT_Budget | M1: AUSP_Budget | N1: SO_Budget | O1: CPAO_Budget
A2: FEANSOLDEP_mean | B2: 127.264 | C2: 8.626 | D2: 29.044 | E2: 10.226 | F2: 18.177 | G2: 28.403 | H2: 30.797 | I2: 7.005 | J2: 3.611 | K2: 3.471 | L2: 4.233 | M2: 1.359 | N2: 0.546 | O2: 17.252
A3: FEBBSOLDEP_mean | B3: 73.407 | C3: 7.036 | D3: 4.964 | E3: 4.97 | F3: 4.804 | G3: 9.773 | H3: 7.249 | I3: 2.169 | J3: 0.814 | K3: 1.373 | L3: 3.256 | M3: 2.421 | N3: 0.626 | O3: 35.912
A4: FEDUSOLDEP_mean | B4: 832.381 | C4: 20.029 | D4: 150.055 | E4: 186.781 | F4: 39.809 | G4: 226.59 | H4: 14.912 | I4: 7.323 | J4: 2.691 | K4: 4.702 | L4: 5.88 | M4: 38.329 | N4: 9.951 | O4: 359.312
A5: FEANTOTDEP_mean | B5: 2221.709 | C5: 70.104 | D5: 655.414 | E5: 119.68 | F5: 256.515 | G5: 376.195 | H5: 845.078 | I5: 82.758 | J5: 44.906 | K5: 38.652 | L5: 64.997 | M5: 22.547 | N5: 5.672 | O5: 98.944
A6: FEBBTOTDEP_mean | B6: 742.651 | C6: 66.491 | D6: 50.059 | E6: 49.636 | F6: 49.13 | G6: 98.767 | H6: 71.97 | I6: 19.162 | J6: 5.858 | K6: 13.427 | L6: 30.179 | M6: 24.244 | N6: 4.148 | O6: 377.631
A7: FEDUTOTDEP_mean | B7: 109175.62 | C7: 2466.404 | D7: 17972.404 | E7: 27875.858 | F7: 2628.346 | G7: 30504.204 | H7: 959.673 | I7: 631.427 | J7: 120.203 | K7: 514.818 | L7: 204.798 | M7: 5474.072 | N7: 692.256 | O7: 50270.384
A8: FESOLDEP_mean | B8: 1033.052 | C8: 35.691 | D8: 184.064 | E8: 201.977 | F8: 62.79 | G8: 264.766 | H8: 52.957 | I8: 16.497 | J8: 7.117 | K8: 9.546 | L8: 13.369 | M8: 42.109 | N8: 11.123 | O8: 412.476
A9: FETOTDEP_mean | B9: 112139.98 | C9: 2602.999 | D9: 18677.877 | E9: 28045.175 | F9: 2933.991 | G9: 30979.165 | H9: 1876.721 | I9: 733.347 | J9: 170.967 | K9: 566.896 | L9: 299.975 | M9: 5520.863 | N9: 702.076 | O9: 50746.959
A11: Variable | B11: Ocean_budget | C11: SATL_Budget_oc | D11: NATL_Budget_oc | E11: AS_Budget_oc | F11: BB_Budget_oc | G11: INDO_budget_oc | H11: SEAS_Budget_oc | I11: NPAC_Budget_oc | J11: ENPAC_Budget_oc | K11: WNPAC_Budget_oc | L11: ARCT_Budget_oc | M11: AUSP_Budget_oc | N11: SO_Budget_oc | O11: CPAO_Budget_oc
A12: FEANSOLDEP_mean | B12: 48.585 | C12: 3.784 | D12: 5 | E12: 5.735 | F12: 6.524 | G12: 12.26 | H12: 13.082 | I12: 5.519 | J12: 3.504 | K12: 2.092 | L12: 0.733 | M12: 0.792 | N12: 0.515 | O12: 6.901
A13: FEBBSOLDEP_mean | B13: 25.899 | C13: 3.036 | D13: 0.824 | E13: 2.242 | F13: 2.306 | G13: 4.548 | H13: 3.039 | I13: 1.141 | J13: 0.763 | K13: 0.396 | L13: 0.167 | M13: 1.089 | N13: 0.6 | O13: 11.456
A14: FEDUSOLDEP_mean | B14: 304.267 | C14: 12.671 | D14: 28.281 | E14: 69.844 | F14: 23.635 | G14: 93.478 | H14: 7.562 | I14: 4.396 | J14: 2.609 | K14: 1.857 | L14: 1.227 | M14: 16.542 | N14: 9.178 | O14: 130.932
A15: FEANTOTDEP_mean | B15: 585.743 | C15: 23.792 | D15: 71.906 | E15: 56.848 | F15: 65.327 | G15: 122.175 | H15: 241.475 | I15: 61.188 | J15: 43.117 | K15: 18.871 | L15: 9.28 | M15: 11.268 | N15: 5.33 | O15: 39.328
A16: FEBBTOTDEP_mean | B16: 215.534 | C16: 23.319 | D16: 7.072 | E16: 17.805 | F16: 19.731 | G16: 37.537 | H16: 27.572 | I16: 7.92 | J16: 5.475 | K16: 2.568 | L16: 1.215 | M16: 8.862 | N16: 3.996 | O16: 98.041
A17: FEDUTOTDEP_mean | B17: 22394.425 | C17: 1219.389 | D17: 2132.289 | E17: 6633.289 | F17: 1447.394 | G17: 8080.683 | H17: 437.701 | I17: 213.685 | J17: 117.578 | K17: 99.702 | L17: 48.226 | M17: 1194.002 | N17: 587.013 | O17: 8481.437
A18: FESOLDEP_mean | B18: 378.751 | C18: 19.49 | D18: 34.106 | E18: 77.821 | F18: 32.465 | G18: 110.286 | H18: 23.682 | I18: 11.056 | J18: 6.876 | K18: 4.345 | L18: 2.127 | M18: 18.423 | N18: 10.293 | O18: 149.289
A19: FETOTDEP_mean | B19: 23195.702 | C19: 1266.5 | D19: 2211.266 | E19: 6707.942 | F19: 1532.453 | G19: 8240.395 | H19: 706.748 | I19: 282.793 | J19: 166.17 | K19: 121.14 | L19: 58.721 | M19: 1214.132 | N19: 596.339 | O19: 8618.807
A22: % contr. AN to all sol Fe | B22: =B12/(B12+B13+B14) -> 0.12827689 | C22: =C12/(C12+C13+C14) -> 0.19414089 | D22: =D12/(D12+D13+D14) -> 0.14660607 | E22: =E12/(E12+E13+E14) -> 0.073694761 | F22: =F12/(F12+F13+F14) -> 0.20095487 | G22: =G12/(G12+G13+G14) -> 0.11116552 | H22: =H12/(H12+H13+H14) -> 0.55237934 | I22: =I12/(I12+I13+I14) -> 0.49918596 | ... O22: =O12/(O12+O13+O14) -> 0.046225777
A23: Relative change to BASE | B23: =Low_BASE!B22-Low_WOOD!B22 -> -0.02948109 | C23: =Low_BASE!C22-Low_WOOD!C22 -> -0.097712314 | D23: =Low_BASE!D22-Low_WOOD!D22 -> -0.028159115 | E23: =Low_BASE!E22-Low_WOOD!E22 -> -0.019186516 | F23: =Low_BASE!F22-Low_WOOD!F22 -> -0.052833487 | G23: =Low_BASE!G22-Low_WOOD!G22 -> -0.029929635 | H23: =Low_BASE!H22-Low_WOOD!H22 -> -0.050218705 | I23: =Low_BASE!I22-Low_WOOD!I22 -> -0.019584534 | ... O23: =Low_BASE!O22-Low_WOOD!O22 -> -0.01457022
A25: Relative change in AN to BASE | B25: =(1-(B12/Low_BASE!B12)) -> -0.34253502 | C25: =(1-(C12/Low_BASE!C12)) -> -1.260454 | D25: =(1-(D12/Low_BASE!D12)) -> -0.27844541 | E25: =(1-(E12/Low_BASE!E12)) -> -0.38026474 | F25: =(1-(F12/Low_BASE!F12)) -> -0.44656319 | G25: =(1-(G12/Low_BASE!G12)) -> -0.41472421 | H25: =(1-(H12/Low_BASE!H12)) -> -0.22364606 | I25: =(1-(I12/Low_BASE!I12)) -> -0.081732654 | ... O25: =(1-(O12/Low_BASE!O12)) -> -0.48281049

Sheet ocean_dep_soluble_only_LOW
A1: Simulation | B1: Scenario | C1: Variable | D1: Ocean_budget | E1: SATL_Budget | F1: NATL_Budget | G1: AS_Budget | H1: BB_Budget | I1: INDO_budget | J1: SEAS_Budget | K1: NPAC_Budget | L1: ENPAC_Budget | M1: WNPAC_Budget | N1: ARCT_Budget | O1: AUSP_Budget | P1: SO_Budget | Q1: CPAO_Budget
A2: V1 | B2: SSP370mid | C2: FEANSOLDEP_mean | D2: 0.03625371 | E2: 0.0015968915 | F2: 0.0030240997 | G2: 0.0045489072 | H2: 0.0048854303 | I2: 0.0094343375 | J2: 0.011179376 | K2: 0.0051294588 | L2: 0.0051294588 | M2: 0.0051294588 | N2: 0.00052359882 | O2: 0.00046931017 | P2: 0.00032628324 | Q2: 0.004570354
A3: V3 | B3: SSP370mid | C3: FEANSOLDEP_mean | D3: 0.07568871 | E3: 0.0042505395 | F3: 0.0070888841 | G3: 0.010330295 | H3: 0.011118847 | I3: 0.021449142 | J3: 0.023351955 | K3: 0.0079184605 | L3: 0.0079184605 | M3: 0.0079184605 | N3: 0.00083099478 | O3: 0.0012301359 | P3: 0.00072680325 | Q3: 0.0088417959
A4: V1 | B4: SSP370end | C4: FEANSOLDEP_mean | D4: 0.028831399 | E4: 0.0011937339 | F4: 0.0024025237 | G4: 0.0038585244 | H4: 0.0037855354 | I4: 0.0076440598 | J4: 0.0082715453 | K4: 0.0037500823 | L4: 0.0037500823 | M4: 0.0037500823 | N4: 0.00045222168 | O4: 0.00033564386 | P4: 0.00026188438 | Q4: 0.0045197038
A5: V3 | B5: SSP370end | C5: FEANSOLDEP_mean | D5: 0.048688867 | E5: 0.0025122757 | F5: 0.0040400736 | G5: 0.0077738391 | H5: 0.0070720537 | I5: 0.014845893 | J5: 0.012472232 | K5: 0.0046609671 | L5: 0.0046609671 | M5: 0.0046609671 | N5: 0.00057474992 | O5: 0.000634796 | P5: 0.00047367231 | Q5: 0.0084742079
A6: V1 | B6: PD | C6: FEANSOLDEP_mean | D6: =Low_BASE!B12*0.001 -> 0.036189 | E6: =Low_BASE!C12*0.001 -> 0.001674 | F6: =Low_BASE!D12*0.001 -> 0.003911 | G6: =Low_BASE!E12*0.001 -> 0.004155 | H6: =Low_BASE!F12*0.001 -> 0.00451 | I6: =Low_BASE!G12*0.001 -> 0.008666 | J6: =Low_BASE!H12*0.001 -> 0.010691 | K6: =Low_BASE!I12*0.001 -> 0.005102 | ... Q6: =Low_BASE!O12*0.001 -> 0.004654
A7: V2 | B7: PD | C7: FEANSOLDEP_mean | D7: =Low_RESI!B12*0.001 -> 0.037354 | E7: =Low_RESI!C12*0.001 -> 0.001697 | F7: =Low_RESI!D12*0.001 -> 0.004072 | G7: =Low_RESI!E12*0.001 -> 0.004285 | H7: =Low_RESI!F12*0.001 -> 0.004672 | I7: =Low_RESI!G12*0.001 -> 0.008957 | J7: =Low_RESI!H12*0.001 -> 0.011184 | K7: =Low_RESI!I12*0.001 -> 0.005215 | ... Q7: =Low_RESI!O12*0.001 -> 0.004697
A8: V3 | B8: PD | C8: FEANSOLDEP_mean | D8: =Low_WOOD!B12*0.001 -> 0.048585 | E8: =Low_WOOD!C12*0.001 -> 0.003784 | F8: =Low_WOOD!D12*0.001 -> 0.005 | G8: =Low_WOOD!E12*0.001 -> 0.005735 | H8: =Low_WOOD!F12*0.001 -> 0.006524 | I8: =Low_WOOD!G12*0.001 -> 0.01226 | J8: =Low_WOOD!H12*0.001 -> 0.013082 | K8: =Low_WOOD!I12*0.001 -> 0.005519 | ... Q8: =Low_WOOD!O12*0.001 -> 0.006901
A9: V1 | B9: PI | C9: FEANSOLDEP_mean | D9: 4.2146529e-05 | E9: 3.3101731e-07 | F9: 7.9332409e-06 | G9: 7.6788678e-06 | H9: 8.2304285e-06 | I9: 1.5909296e-05 | J9: 8.6004481e-06 | K9: 2.7031065e-06 | L9: 2.7031065e-06 | M9: 2.7031065e-06 | N9: 1.0167667e-06 | O9: 2.7349798e-07 | P9: 1.3719005e-07 | Q9: 5.2419648e-06
A10: V3 | B10: PI | C10: FEANSOLDEP_mean | D10: 4.2146529e-05 | E10: 3.3101731e-07 | F10: 7.9332409e-06 | G10: 7.6788678e-06 | H10: 8.2304285e-06 | I10: 1.5909296e-05 | J10: 8.6004481e-06 | K10: 2.7031065e-06 | L10: 2.7031065e-06 | M10: 2.7031065e-06 | N10: 1.0167667e-06 | O10: 2.7349798e-07 | P10: 1.3719005e-07 | Q10: 5.2419648e-06
A11: V1 | B11: SSP370mid | C11: FEBBSOLDEP_mean | D11: 0.025632377 | E11: 0.0030808448 | F11: 0.00087537307 | G11: 0.0019873361 | H11: 0.0035749645 | I11: 0.0055623005 | J11: 0.0042741562 | K11: 0.0014355441 | L11: 0.0014355441 | M11: 0.0014355441 | N11: 0.00017578591 | O11: 0.0013213256 | P11: 0.00057596816 | Q11: 0.0083310787
A12: V3 | B12: SSP370mid | C12: FEBBSOLDEP_mean | D12: 0.02563428 | E12: 0.0030818985 | F12: 0.00087537567 | G12: 0.001987362 | H12: 0.0035751461 | I12: 0.0055625081 | J12: 0.0042742144 | K12: 0.0014356961 | L12: 0.0014356961 | M12: 0.0014356961 | N12: 0.00017580105 | O12: 0.0013213651 | P12: 0.00057593403 | Q12: 0.0083314868
A13: V1 | B13: SSP370end | C13: FEBBSOLDEP_mean | D13: 0.024742145 | E13: 0.0027422827 | F13: 0.00088559515 | G13: 0.001923601 | H13: 0.0034379271 | I13: 0.005361528 | J13: 0.0041616318 | K13: 0.001434976 | L13: 0.001434976 | M13: 0.001434976 | N13: 0.00017798797 | O13: 0.0013102638 | P13: 0.00054865607 | Q13: 0.0081192237
A14: V3 | B14: SSP370end | C14: FEBBSOLDEP_mean | D14: 0.024740587 | E14: 0.0027410963 | F14: 0.00088555687 | G14: 0.0019235964 | H14: 0.0034372095 | I14: 0.0053608059 | J14: 0.0041617881 | K14: 0.0014349769 | L14: 0.0014349769 | M14: 0.0014349769 | N14: 0.00017801224 | O14: 0.0013103606 | P14: 0.00054870411 | Q14: 0.0081192862
A15: V1 | B15: PD | C15: FEBBSOLDEP_mean | D15: =Low_BASE!B13*0.001 -> 0.025903 | E15: =Low_BASE!C13*0.001 -> 0.003038 | F15: =Low_BASE!D13*0.001 -> 0.000825 | G15: =Low_BASE!E13*0.001 -> 0.002242 | H15: =Low_BASE!F13*0.001 -> 0.002305 | I15: =Low_BASE!G13*0.001 -> 0.004547 | J15: =Low_BASE!H13*0.001 -> 0.003039 | K15: =Low_BASE!I13*0.001 -> 0.001141 | ... Q15: =Low_BASE!O13*0.001 -> 0.011457
A16: V2 | B16: PD | C16: FEBBSOLDEP_mean | D16: 0.025913861 | E16: 0.0030418274 | F16: 0.00082446672 | G16: 0.0022428263 | H16: 0.0023061785 | I16: 0.0045490048 | J16: 0.0030399013 | K16: 0.0011413862 | L16: 0.0011413862 | M16: 0.0011413862 | N16: 0.00016688468 | O16: 0.0010892009 | P16: 0.00060019807 | Q16: 0.01146099
A17: V3 | B17: PD | C17: FEBBSOLDEP_mean | D17: 0.025910233 | E17: 0.0030392764 | F17: 0.00082448366 | G17: 0.0022426127 | H17: 0.002306218 | I17: 0.0045488307 | J17: 0.0030397406 | K17: 0.0011413396 | L17: 0.0011413396 | M17: 0.0011413396 | N17: 0.00016693016 | O17: 0.0010891571 | P17: 0.00060006879 | Q17: 0.011460406
A18: V1 | B18: PI | C18: FEBBSOLDEP_mean | D18: 0.048614641 | E18: 0.012503054 | F18: 0.0030122422 | G18: 0.0037890532 | H18: 0.0028939269 | I18: 0.0066829801 | J18: 0.0045278814 | K18: 0.0025121785 | L18: 0.0025121785 | M18: 0.0025121785 | N18: 0.000573717 | O18: 0.0013407074 | P18: 0.0016286736 | Q18: 0.015833206
A19: V3 | B19: PI | C19: FEBBSOLDEP_mean | D19: 0.0486 | E19: 0.0125 | F19: 0.003 | G19: 0.0038 | H19: 0.0029 | I19: 0.0067 | J19: 0.0045 | K19: 0.0025 | L19: 0.0025 | M19: 0.0025 | N19: 0.0006 | O19: 0.0013 | P19: 0.0016 | Q19: 0.0158
A20: V1 | B20: SSP370mid | C20: FEDUSOLDEP_mean | D20: 0.31511086 | E20: 0.013792339 | F20: 0.02961793 | G20: 0.071313733 | H20: 0.024030682 | I20: 0.095344415 | J20: 0.0076958801 | K20: 0.0045100481 | L20: 0.0045100481 | M20: 0.0045100481 | N20: 0.0012834713 | O20: 0.016867353 | P20: 0.009705935 | Q20: 0.13629349
A21: V3 | B21: SSP370mid | C21: FEDUSOLDEP_mean | D21: 0.31510671 | E21: 0.013774977 | F21: 0.029614084 | G21: 0.071310099 | H21: 0.024026343 | I21: 0.095336442 | J21: 0.0076890834 | K21: 0.0045067221 | L21: 0.0045067221 | M21: 0.0045067221 | N21: 0.0012826236 | O21: 0.016870467 | P21: 0.00969763 | Q21: 0.13633468
A22: V1 | B22: SSP370end | C22: FEDUSOLDEP_mean | D22: 0.33179869 | E22: 0.015127593 | F22: 0.031219288 | G22: 0.0736274 | H22: 0.026066321 | I22: 0.099693721 | J22: 0.0085015321 | K22: 0.0046852938 | L22: 0.0046852938 | M22: 0.0046852938 | N22: 0.0013590797 | O22: 0.020610753 | P22: 0.01110086 | Q22: 0.13950057
A23: V3 | B23: SSP370end | C23: FEDUSOLDEP_mean | D23: 0.33179464 | E23: 0.015108691 | F23: 0.031215807 | G23: 0.073624507 | H23: 0.02606257 | I23: 0.099687078 | J23: 0.0084940376 | K23: 0.0046818943 | L23: 0.0046818943 | M23: 0.0046818943 | N23: 0.0013581689 | O23: 0.020614472 | P23: 0.011091752 | Q23: 0.13954274
A24: V1 | B24: PD | C24: FEDUSOLDEP_mean | D24: 0.30493875 | E24: 0.012677537 | F24: 0.028371218 | G24: 0.069940304 | H24: 0.023678805 | I24: 0.093619109 | J24: 0.0075710426 | K24: 0.0044055343 | L24: 0.0044055343 | M24: 0.0044055343 | N24: 0.0012330766 | O24: 0.016534839 | P24: 0.009177634 | Q24: 0.13134876
A25: V2 | B25: PD | C25: FEDUSOLDEP_mean | D25: 0.30494548 | E25: 0.012678 | F25: 0.028359201 | G25: 0.069953351 | H25: 0.023677777 | I25: 0.093631128 | J25: 0.0075688912 | K25: 0.0044056058 | L25: 0.0044056058 | M25: 0.0044056058 | N25: 0.0012333984 | O25: 0.016533098 | P25: 0.0091679845 | Q25: 0.13136817
A26: V3 | B26: PD | C26: FEDUSOLDEP_mean | D26: 0.3049343 | E26: 0.012661416 | F26: 0.028367259 | G26: 0.069936052 | H26: 0.023674529 | I26: 0.093610581 | J26: 0.007564369 | K26: 0.0044022559 | L26: 0.0044022559 | M26: 0.0044022559 | N26: 0.0012322713 | O26: 0.016537817 | P26: 0.0091699105 | Q26: 0.13138842
A27: V1 | B27: PI | C27: FEDUSOLDEP_mean | D27: 0.23390925 | E27: 0.01046645 | F27: 0.021392115 | G27: 0.051225156 | H27: 0.016820011 | I27: 0.068045167 | J27: 0.0060056526 | K27: 0.0037755138 | L27: 0.0037755138 | M27: 0.0037755138 | N27: 0.0009107211 | O27: 0.013373043 | P27: 0.0073574001 | Q27: 0.10258319
A28: V3 | B28: PI | C28: FEDUSOLDEP_mean | D28: 0.2339 | E28: 0.0104 | F28: 0.0214 | G28: 0.0512 | H28: 0.0168 | I28: 0.068 | J28: 0.006 | K28: 0.0038 | L28: 0.0038 | M28: 0.0038 | N28: 0.0009 | O28: 0.0134 | P28: 0.0074 | Q28: 0.1026
C91: v1 (sum) | D91: =(D6+D15+D24)*1000 -> 367.03075
D92: =D6*1000 -> 36.189 | E92: =D92/D$91 -> 0.098599368
D93: =D15*1000 -> 25.903 | E93: =D93/D$91 -> 0.070574468
D94: =D24*1000 -> 304.93875 | E94: =D94/D$91 -> 0.83082616
C95: v2 (sum) | D95: =SUM(D7+D16+D25)*1000 -> 368.21334
D96: =D7*1000 -> 37.354 | E96: =D96/D$95 -> 0.10144662
D97: 25.907408 | E97: =D97/D$95 -> 0.070359775
D98: 304.93875 | E98: =D98/D$95 -> 0.8281578
C99: v3 (sum) | D99: =SUM(D8+D17+D26)*1000 -> 379.42954
D100: =D8*1000 -> 48.585 | E100: =D100/D$99 -> 0.12804749
D101: 25.907408 | E101: =D101/D$99 -> 0.068279892
D102: 304.93875 | E102: =D102/D$99 -> 0.80367689
...
